{
  "version": 1,
  "models": {
    "player": {
      "voxelSize": 4,
      "voxels": [
        {
          "x": -1,
          "y": -1,
          "z": 0,
          "color": "#0d121a"
        },
        {
          "x": -1,
          "y": 0,
          "z": 0,
          "color": "#0d121a"
        },
        {
          "x": 1,
          "y": -1,
          "z": 0,
          "color": "#0d121a"
        },
        {
          "x": 1,
          "y": 0,
          "z": 0,
          "color": "#0d121a"
        },
        {
          "x": -1,
          "y": -1,
          "z": 1,
          "color": "#22334a"
        },
        {
          "x": -1,
          "y": 0,
          "z": 1,
          "color": "#22334a"
        },
        {
          "x": 1,
          "y": -1,
          "z": 1,
          "color": "#22334a"
        },
        {
          "x": 1,
          "y": 0,
          "z": 1,
          "color": "#22334a"
        },
        {
          "x": -1,
          "y": -1,
          "z": 2,
          "color": "#22334a"
        },
        {
          "x": -1,
          "y": 0,
          "z": 2,
          "color": "#22334a"
        },
        {
          "x": 0,
          "y": -1,
          "z": 2,
          "color": "#22334a"
        },
        {
          "x": 0,
          "y": 0,
          "z": 2,
          "color": "#22334a"
        },
        {
          "x": 1,
          "y": -1,
          "z": 2,
          "color": "#22334a"
        },
        {
          "x": 1,
          "y": 0,
          "z": 2,
          "color": "#22334a"
        },
        {
          "x": -1,
          "y": -1,
          "z": 3,
          "color": "#3ec4ff"
        },
        {
          "x": -1,
          "y": -1,
          "z": 4,
          "color": "#3ec4ff"
        },
        {
          "x": -1,
          "y": 0,
          "z": 3,
          "color": "#3ec4ff"
        },
        {
          "x": -1,
          "y": 0,
          "z": 4,
          "color": "#3ec4ff"
        },
        {
          "x": 0,
          "y": -1,
          "z": 3,
          "color": "#3ec4ff"
        },
        {
          "x": 0,
          "y": -1,
          "z": 4,
          "color": "#bfe9ff"
        },
        {
          "x": 0,
          "y": 0,
          "z": 3,
          "color": "#3ec4ff"
        },
        {
          "x": 0,
          "y": 0,
          "z": 4,
          "color": "#3ec4ff"
        },
        {
          "x": 1,
          "y": -1,
          "z": 3,
          "color": "#bfe9ff"
        },
        {
          "x": 1,
          "y": -1,
          "z": 4,
          "color": "#3ec4ff"
        },
        {
          "x": 1,
          "y": 0,
          "z": 3,
          "color": "#3ec4ff"
        },
        {
          "x": 1,
          "y": 0,
          "z": 4,
          "color": "#3ec4ff"
        },
        {
          "x": -1,
          "y": -1,
          "z": 5,
          "color": "#3ec4ff"
        },
        {
          "x": -1,
          "y": 0,
          "z": 5,
          "color": "#3ec4ff"
        },
        {
          "x": 0,
          "y": -1,
          "z": 5,
          "color": "#f4d7c5"
        },
        {
          "x": 0,
          "y": 0,
          "z": 5,
          "color": "#f4d7c5"
        },
        {
          "x": 1,
          "y": -1,
          "z": 5,
          "color": "#3ec4ff"
        },
        {
          "x": 1,
          "y": 0,
          "z": 5,
          "color": "#3ec4ff"
        },
        {
          "x": -2,
          "y": -1,
          "z": 3,
          "color": "#f4d7c5"
        },
        {
          "x": -2,
          "y": -1,
          "z": 4,
          "color": "#3ec4ff"
        },
        {
          "x": -2,
          "y": 0,
          "z": 3,
          "color": "#3ec4ff"
        },
        {
          "x": -2,
          "y": 0,
          "z": 4,
          "color": "#3ec4ff"
        },
        {
          "x": 2,
          "y": -1,
          "z": 3,
          "color": "#f4d7c5"
        },
        {
          "x": 2,
          "y": -1,
          "z": 4,
          "color": "#3ec4ff"
        },
        {
          "x": 2,
          "y": 0,
          "z": 3,
          "color": "#3ec4ff"
        },
        {
          "x": 2,
          "y": 0,
          "z": 4,
          "color": "#3ec4ff"
        },
        {
          "x": -1,
          "y": -1,
          "z": 6,
          "color": "#f4d7c5"
        },
        {
          "x": -1,
          "y": -1,
          "z": 7,
          "color": "#f4d7c5"
        },
        {
          "x": -1,
          "y": 0,
          "z": 6,
          "color": "#f4d7c5"
        },
        {
          "x": -1,
          "y": 0,
          "z": 7,
          "color": "#3a2a1a"
        },
        {
          "x": 0,
          "y": -1,
          "z": 6,
          "color": "#f4d7c5"
        },
        {
          "x": 0,
          "y": -1,
          "z": 7,
          "color": "#f4d7c5"
        },
        {
          "x": 0,
          "y": 0,
          "z": 6,
          "color": "#f4d7c5"
        },
        {
          "x": 0,
          "y": 0,
          "z": 7,
          "color": "#3a2a1a"
        },
        {
          "x": 1,
          "y": -1,
          "z": 6,
          "color": "#000000"
        },
        {
          "x": 1,
          "y": -1,
          "z": 7,
          "color": "#f4d7c5"
        },
        {
          "x": 1,
          "y": 0,
          "z": 6,
          "color": "#f4d7c5"
        },
        {
          "x": 1,
          "y": 0,
          "z": 7,
          "color": "#3a2a1a"
        },
        {
          "x": -1,
          "y": -1,
          "z": 8,
          "color": "#3a2a1a"
        },
        {
          "x": -1,
          "y": 0,
          "z": 8,
          "color": "#3a2a1a"
        },
        {
          "x": 0,
          "y": -1,
          "z": 8,
          "color": "#3a2a1a"
        },
        {
          "x": 0,
          "y": 0,
          "z": 8,
          "color": "#3a2a1a"
        },
        {
          "x": 1,
          "y": -1,
          "z": 8,
          "color": "#3a2a1a"
        },
        {
          "x": 1,
          "y": 0,
          "z": 8,
          "color": "#3a2a1a"
        }
      ],
      "baseRotation": {
        "x": 0,
        "y": 0,
        "z": 0
      },
      "dynamic": false
    },
    "raptor": {
      "voxelSize": 3,
      "voxels": [
        {
          "x": -3,
          "y": -1,
          "z": -1,
          "color": "#f0f0e8"
        },
        {
          "x": -2,
          "y": -1,
          "z": -1,
          "color": "#f0f0e8"
        },
        {
          "x": -1,
          "y": -1,
          "z": -1,
          "color": "#f0f0e8"
        },
        {
          "x": 0,
          "y": -1,
          "z": -1,
          "color": "#f0f0e8"
        },
        {
          "x": 1,
          "y": -1,
          "z": -1,
          "color": "#f0f0e8"
        },
        {
          "x": 2,
          "y": -1,
          "z": -1,
          "color": "#f0f0e8"
        },
        {
          "x": -3,
          "y": 0,
          "z": -1,
          "color": "#f0f0e8"
        },
        {
          "x": -2,
          "y": 0,
          "z": -1,
          "color": "#f0f0e8"
        },
        {
          "x": 0,
          "y": 0,
          "z": -1,
          "color": "#f0f0e8"
        },
        {
          "x": 1,
          "y": 0,
          "z": -1,
          "color": "#f0f0e8"
        },
        {
          "x": -3,
          "y": -1,
          "z": 0,
          "color": "#1b2418"
        },
        {
          "x": -2,
          "y": -1,
          "z": 0,
          "color": "#1b2418"
        },
        {
          "x": 0,
          "y": -1,
          "z": 0,
          "color": "#1b2418"
        },
        {
          "x": 1,
          "y": -1,
          "z": 0,
          "color": "#1b2418"
        },
        {
          "x": -3,
          "y": 0,
          "z": 0,
          "color": "#1b2418"
        },
        {
          "x": -2,
          "y": 0,
          "z": 0,
          "color": "#1b2418"
        },
        {
          "x": 0,
          "y": 0,
          "z": 0,
          "color": "#1b2418"
        },
        {
          "x": 1,
          "y": 0,
          "z": 0,
          "color": "#1b2418"
        },
        {
          "x": -3,
          "y": -1,
          "z": 1,
          "color": "#1b2418"
        },
        {
          "x": -2,
          "y": -1,
          "z": 1,
          "color": "#1b2418"
        },
        {
          "x": 0,
          "y": -1,
          "z": 1,
          "color": "#1b2418"
        },
        {
          "x": 1,
          "y": -1,
          "z": 1,
          "color": "#1b2418"
        },
        {
          "x": -3,
          "y": 0,
          "z": 1,
          "color": "#1b2418"
        },
        {
          "x": -2,
          "y": 0,
          "z": 1,
          "color": "#1b2418"
        },
        {
          "x": 0,
          "y": 0,
          "z": 1,
          "color": "#1b2418"
        },
        {
          "x": 1,
          "y": 0,
          "z": 1,
          "color": "#1b2418"
        },
        {
          "x": -11,
          "y": -1,
          "z": 2,
          "color": "#1b2418"
        },
        {
          "x": -3,
          "y": -1,
          "z": 2,
          "color": "#1b2418"
        },
        {
          "x": -2,
          "y": -1,
          "z": 2,
          "color": "#1b2418"
        },
        {
          "x": 0,
          "y": -1,
          "z": 2,
          "color": "#1b2418"
        },
        {
          "x": 1,
          "y": -1,
          "z": 2,
          "color": "#1b2418"
        },
        {
          "x": -9,
          "y": 0,
          "z": 2,
          "color": "#1b2418"
        },
        {
          "x": -3,
          "y": 0,
          "z": 2,
          "color": "#1b2418"
        },
        {
          "x": -2,
          "y": 0,
          "z": 2,
          "color": "#1b2418"
        },
        {
          "x": 0,
          "y": 0,
          "z": 2,
          "color": "#1b2418"
        },
        {
          "x": 1,
          "y": 0,
          "z": 2,
          "color": "#1b2418"
        },
        {
          "x": 2,
          "y": -2,
          "z": 3,
          "color": "#f0f0e8"
        },
        {
          "x": -11,
          "y": -1,
          "z": 3,
          "color": "#5f6f38"
        },
        {
          "x": -10,
          "y": -1,
          "z": 3,
          "color": "#5f6f38"
        },
        {
          "x": -9,
          "y": -1,
          "z": 3,
          "color": "#5f6f38"
        },
        {
          "x": -8,
          "y": -1,
          "z": 3,
          "color": "#5f6f38"
        },
        {
          "x": -7,
          "y": -1,
          "z": 3,
          "color": "#5f6f38"
        },
        {
          "x": -3,
          "y": -1,
          "z": 3,
          "color": "#1b2418"
        },
        {
          "x": -2,
          "y": -1,
          "z": 3,
          "color": "#1b2418"
        },
        {
          "x": -1,
          "y": -1,
          "z": 3,
          "color": "#7f8d55"
        },
        {
          "x": 0,
          "y": -1,
          "z": 3,
          "color": "#1b2418"
        },
        {
          "x": 1,
          "y": -1,
          "z": 3,
          "color": "#1b2418"
        },
        {
          "x": -11,
          "y": 0,
          "z": 3,
          "color": "#5f6f38"
        },
        {
          "x": -10,
          "y": 0,
          "z": 3,
          "color": "#5f6f38"
        },
        {
          "x": -9,
          "y": 0,
          "z": 3,
          "color": "#5f6f38"
        },
        {
          "x": -8,
          "y": 0,
          "z": 3,
          "color": "#5f6f38"
        },
        {
          "x": -7,
          "y": 0,
          "z": 3,
          "color": "#5f6f38"
        },
        {
          "x": -3,
          "y": 0,
          "z": 3,
          "color": "#1b2418"
        },
        {
          "x": -2,
          "y": 0,
          "z": 3,
          "color": "#1b2418"
        },
        {
          "x": -1,
          "y": 0,
          "z": 3,
          "color": "#7f8d55"
        },
        {
          "x": 0,
          "y": 0,
          "z": 3,
          "color": "#1b2418"
        },
        {
          "x": 1,
          "y": 0,
          "z": 3,
          "color": "#1b2418"
        },
        {
          "x": 2,
          "y": 1,
          "z": 3,
          "color": "#f0f0e8"
        },
        {
          "x": 1,
          "y": -2,
          "z": 4,
          "color": "#5f6f38"
        },
        {
          "x": 2,
          "y": -2,
          "z": 4,
          "color": "#5f6f38"
        },
        {
          "x": -10,
          "y": -1,
          "z": 4,
          "color": "#26311f"
        },
        {
          "x": -8,
          "y": -1,
          "z": 4,
          "color": "#5f6f38"
        },
        {
          "x": -7,
          "y": -1,
          "z": 4,
          "color": "#5f6f38"
        },
        {
          "x": -6,
          "y": -1,
          "z": 4,
          "color": "#5f6f38"
        },
        {
          "x": -5,
          "y": -1,
          "z": 4,
          "color": "#5f6f38"
        },
        {
          "x": -4,
          "y": -1,
          "z": 4,
          "color": "#5f6f38"
        },
        {
          "x": -3,
          "y": -1,
          "z": 4,
          "color": "#5f6f38"
        },
        {
          "x": -2,
          "y": -1,
          "z": 4,
          "color": "#5f6f38"
        },
        {
          "x": -1,
          "y": -1,
          "z": 4,
          "color": "#5f6f38"
        },
        {
          "x": 0,
          "y": -1,
          "z": 4,
          "color": "#5f6f38"
        },
        {
          "x": 1,
          "y": -1,
          "z": 4,
          "color": "#5f6f38"
        },
        {
          "x": -8,
          "y": 0,
          "z": 4,
          "color": "#5f6f38"
        },
        {
          "x": -7,
          "y": 0,
          "z": 4,
          "color": "#5f6f38"
        },
        {
          "x": -6,
          "y": 0,
          "z": 4,
          "color": "#5f6f38"
        },
        {
          "x": -5,
          "y": 0,
          "z": 4,
          "color": "#5f6f38"
        },
        {
          "x": -4,
          "y": 0,
          "z": 4,
          "color": "#1b2418"
        },
        {
          "x": -3,
          "y": 0,
          "z": 4,
          "color": "#5f6f38"
        },
        {
          "x": -2,
          "y": 0,
          "z": 4,
          "color": "#5f6f38"
        },
        {
          "x": -1,
          "y": 0,
          "z": 4,
          "color": "#5f6f38"
        },
        {
          "x": 0,
          "y": 0,
          "z": 4,
          "color": "#5f6f38"
        },
        {
          "x": 1,
          "y": 0,
          "z": 4,
          "color": "#5f6f38"
        },
        {
          "x": 1,
          "y": 1,
          "z": 4,
          "color": "#5f6f38"
        },
        {
          "x": 2,
          "y": 1,
          "z": 4,
          "color": "#5f6f38"
        },
        {
          "x": 1,
          "y": -2,
          "z": 5,
          "color": "#5f6f38"
        },
        {
          "x": 2,
          "y": -2,
          "z": 5,
          "color": "#5f6f38"
        },
        {
          "x": -6,
          "y": -1,
          "z": 5,
          "color": "#5f6f38"
        },
        {
          "x": -5,
          "y": -1,
          "z": 5,
          "color": "#5f6f38"
        },
        {
          "x": -4,
          "y": -1,
          "z": 5,
          "color": "#1b2418"
        },
        {
          "x": -3,
          "y": -1,
          "z": 5,
          "color": "#5f6f38"
        },
        {
          "x": -2,
          "y": -1,
          "z": 5,
          "color": "#5f6f38"
        },
        {
          "x": -1,
          "y": -1,
          "z": 5,
          "color": "#5f6f38"
        },
        {
          "x": 0,
          "y": -1,
          "z": 5,
          "color": "#5f6f38"
        },
        {
          "x": 1,
          "y": -1,
          "z": 5,
          "color": "#5f6f38"
        },
        {
          "x": 2,
          "y": -1,
          "z": 5,
          "color": "#5f6f38"
        },
        {
          "x": -8,
          "y": 0,
          "z": 5,
          "color": "#26311f"
        },
        {
          "x": -6,
          "y": 0,
          "z": 5,
          "color": "#5f6f38"
        },
        {
          "x": -5,
          "y": 0,
          "z": 5,
          "color": "#5f6f38"
        },
        {
          "x": -4,
          "y": 0,
          "z": 5,
          "color": "#5f6f38"
        },
        {
          "x": -3,
          "y": 0,
          "z": 5,
          "color": "#5f6f38"
        },
        {
          "x": -2,
          "y": 0,
          "z": 5,
          "color": "#5f6f38"
        },
        {
          "x": -1,
          "y": 0,
          "z": 5,
          "color": "#5f6f38"
        },
        {
          "x": 0,
          "y": 0,
          "z": 5,
          "color": "#5f6f38"
        },
        {
          "x": 1,
          "y": 0,
          "z": 5,
          "color": "#5f6f38"
        },
        {
          "x": 2,
          "y": 0,
          "z": 5,
          "color": "#1b2418"
        },
        {
          "x": 1,
          "y": 1,
          "z": 5,
          "color": "#5f6f38"
        },
        {
          "x": 2,
          "y": 1,
          "z": 5,
          "color": "#5f6f38"
        },
        {
          "x": -6,
          "y": -1,
          "z": 6,
          "color": "#26311f"
        },
        {
          "x": -4,
          "y": -1,
          "z": 6,
          "color": "#5f6f38"
        },
        {
          "x": -3,
          "y": -1,
          "z": 6,
          "color": "#5f6f38"
        },
        {
          "x": -2,
          "y": -1,
          "z": 6,
          "color": "#5f6f38"
        },
        {
          "x": -1,
          "y": -1,
          "z": 6,
          "color": "#5f6f38"
        },
        {
          "x": 0,
          "y": -1,
          "z": 6,
          "color": "#5f6f38"
        },
        {
          "x": 1,
          "y": -1,
          "z": 6,
          "color": "#5f6f38"
        },
        {
          "x": 2,
          "y": -1,
          "z": 6,
          "color": "#5f6f38"
        },
        {
          "x": -4,
          "y": 0,
          "z": 6,
          "color": "#5f6f38"
        },
        {
          "x": -3,
          "y": 0,
          "z": 6,
          "color": "#5f6f38"
        },
        {
          "x": -2,
          "y": 0,
          "z": 6,
          "color": "#5f6f38"
        },
        {
          "x": -1,
          "y": 0,
          "z": 6,
          "color": "#5f6f38"
        },
        {
          "x": 0,
          "y": 0,
          "z": 6,
          "color": "#5f6f38"
        },
        {
          "x": 1,
          "y": 0,
          "z": 6,
          "color": "#5f6f38"
        },
        {
          "x": 2,
          "y": 0,
          "z": 6,
          "color": "#5f6f38"
        },
        {
          "x": -3,
          "y": -1,
          "z": 7,
          "color": "#26311f"
        },
        {
          "x": -2,
          "y": -1,
          "z": 7,
          "color": "#718249"
        },
        {
          "x": -1,
          "y": -1,
          "z": 7,
          "color": "#718249"
        },
        {
          "x": 0,
          "y": -1,
          "z": 7,
          "color": "#718249"
        },
        {
          "x": 1,
          "y": -1,
          "z": 7,
          "color": "#26311f"
        },
        {
          "x": 2,
          "y": -1,
          "z": 7,
          "color": "#5f6f38"
        },
        {
          "x": 3,
          "y": -1,
          "z": 7,
          "color": "#1b2418"
        },
        {
          "x": -2,
          "y": 0,
          "z": 7,
          "color": "#718249"
        },
        {
          "x": -1,
          "y": 0,
          "z": 7,
          "color": "#718249"
        },
        {
          "x": 0,
          "y": 0,
          "z": 7,
          "color": "#718249"
        },
        {
          "x": 1,
          "y": 0,
          "z": 7,
          "color": "#718249"
        },
        {
          "x": 2,
          "y": 0,
          "z": 7,
          "color": "#5f6f38"
        },
        {
          "x": 3,
          "y": 0,
          "z": 7,
          "color": "#1b2418"
        },
        {
          "x": 8,
          "y": -2,
          "z": 8,
          "color": "#1b2418"
        },
        {
          "x": 9,
          "y": -2,
          "z": 8,
          "color": "#1b2418"
        },
        {
          "x": 10,
          "y": -2,
          "z": 8,
          "color": "#1b2418"
        },
        {
          "x": 11,
          "y": -2,
          "z": 8,
          "color": "#1b2418"
        },
        {
          "x": 2,
          "y": -1,
          "z": 8,
          "color": "#5f6f38"
        },
        {
          "x": 3,
          "y": -1,
          "z": 8,
          "color": "#5f6f38"
        },
        {
          "x": 4,
          "y": -1,
          "z": 8,
          "color": "#1b2418"
        },
        {
          "x": 8,
          "y": -1,
          "z": 8,
          "color": "#1b2418"
        },
        {
          "x": 9,
          "y": -1,
          "z": 8,
          "color": "#1b2418"
        },
        {
          "x": 10,
          "y": -1,
          "z": 8,
          "color": "#1b2418"
        },
        {
          "x": 11,
          "y": -1,
          "z": 8,
          "color": "#1b2418"
        },
        {
          "x": -1,
          "y": 0,
          "z": 8,
          "color": "#26311f"
        },
        {
          "x": 2,
          "y": 0,
          "z": 8,
          "color": "#5f6f38"
        },
        {
          "x": 3,
          "y": 0,
          "z": 8,
          "color": "#5f6f38"
        },
        {
          "x": 4,
          "y": 0,
          "z": 8,
          "color": "#1b2418"
        },
        {
          "x": 8,
          "y": 0,
          "z": 8,
          "color": "#1b2418"
        },
        {
          "x": 9,
          "y": 0,
          "z": 8,
          "color": "#1b2418"
        },
        {
          "x": 10,
          "y": 0,
          "z": 8,
          "color": "#1b2418"
        },
        {
          "x": 11,
          "y": 0,
          "z": 8,
          "color": "#1b2418"
        },
        {
          "x": 8,
          "y": 1,
          "z": 8,
          "color": "#1b2418"
        },
        {
          "x": 9,
          "y": 1,
          "z": 8,
          "color": "#1b2418"
        },
        {
          "x": 10,
          "y": 1,
          "z": 8,
          "color": "#1b2418"
        },
        {
          "x": 11,
          "y": 1,
          "z": 8,
          "color": "#1b2418"
        },
        {
          "x": 8,
          "y": -2,
          "z": 9,
          "color": "#5f6f38"
        },
        {
          "x": 9,
          "y": -2,
          "z": 9,
          "color": "#5f6f38"
        },
        {
          "x": 10,
          "y": -2,
          "z": 9,
          "color": "#5f6f38"
        },
        {
          "x": 11,
          "y": -2,
          "z": 9,
          "color": "#1a120f"
        },
        {
          "x": 3,
          "y": -1,
          "z": 9,
          "color": "#5f6f38"
        },
        {
          "x": 4,
          "y": -1,
          "z": 9,
          "color": "#5f6f38"
        },
        {
          "x": 8,
          "y": -1,
          "z": 9,
          "color": "#5f6f38"
        },
        {
          "x": 9,
          "y": -1,
          "z": 9,
          "color": "#5f6f38"
        },
        {
          "x": 10,
          "y": -1,
          "z": 9,
          "color": "#5f6f38"
        },
        {
          "x": 11,
          "y": -1,
          "z": 9,
          "color": "#5f6f38"
        },
        {
          "x": 3,
          "y": 0,
          "z": 9,
          "color": "#5f6f38"
        },
        {
          "x": 4,
          "y": 0,
          "z": 9,
          "color": "#5f6f38"
        },
        {
          "x": 8,
          "y": 0,
          "z": 9,
          "color": "#5f6f38"
        },
        {
          "x": 9,
          "y": 0,
          "z": 9,
          "color": "#5f6f38"
        },
        {
          "x": 10,
          "y": 0,
          "z": 9,
          "color": "#5f6f38"
        },
        {
          "x": 11,
          "y": 0,
          "z": 9,
          "color": "#5f6f38"
        },
        {
          "x": 8,
          "y": 1,
          "z": 9,
          "color": "#1b2418"
        },
        {
          "x": 9,
          "y": 1,
          "z": 9,
          "color": "#5f6f38"
        },
        {
          "x": 10,
          "y": 1,
          "z": 9,
          "color": "#5f6f38"
        },
        {
          "x": 11,
          "y": 1,
          "z": 9,
          "color": "#1a120f"
        },
        {
          "x": 5,
          "y": -2,
          "z": 10,
          "color": "#5f6f38"
        },
        {
          "x": 6,
          "y": -2,
          "z": 10,
          "color": "#5f6f38"
        },
        {
          "x": 7,
          "y": -2,
          "z": 10,
          "color": "#5f6f38"
        },
        {
          "x": 8,
          "y": -2,
          "z": 10,
          "color": "#5f6f38"
        },
        {
          "x": 9,
          "y": -2,
          "z": 10,
          "color": "#5f6f38"
        },
        {
          "x": 10,
          "y": -2,
          "z": 10,
          "color": "#1a120f"
        },
        {
          "x": 11,
          "y": -2,
          "z": 10,
          "color": "#5f6f38"
        },
        {
          "x": 4,
          "y": -1,
          "z": 10,
          "color": "#5f6f38"
        },
        {
          "x": 5,
          "y": -1,
          "z": 10,
          "color": "#5f6f38"
        },
        {
          "x": 6,
          "y": -1,
          "z": 10,
          "color": "#5f6f38"
        },
        {
          "x": 7,
          "y": -1,
          "z": 10,
          "color": "#5f6f38"
        },
        {
          "x": 8,
          "y": -1,
          "z": 10,
          "color": "#5f6f38"
        },
        {
          "x": 9,
          "y": -1,
          "z": 10,
          "color": "#5f6f38"
        },
        {
          "x": 10,
          "y": -1,
          "z": 10,
          "color": "#5f6f38"
        },
        {
          "x": 11,
          "y": -1,
          "z": 10,
          "color": "#5f6f38"
        },
        {
          "x": 4,
          "y": 0,
          "z": 10,
          "color": "#5f6f38"
        },
        {
          "x": 5,
          "y": 0,
          "z": 10,
          "color": "#5f6f38"
        },
        {
          "x": 6,
          "y": 0,
          "z": 10,
          "color": "#5f6f38"
        },
        {
          "x": 7,
          "y": 0,
          "z": 10,
          "color": "#5f6f38"
        },
        {
          "x": 8,
          "y": 0,
          "z": 10,
          "color": "#5f6f38"
        },
        {
          "x": 9,
          "y": 0,
          "z": 10,
          "color": "#5f6f38"
        },
        {
          "x": 10,
          "y": 0,
          "z": 10,
          "color": "#5f6f38"
        },
        {
          "x": 11,
          "y": 0,
          "z": 10,
          "color": "#5f6f38"
        },
        {
          "x": 5,
          "y": 1,
          "z": 10,
          "color": "#5f6f38"
        },
        {
          "x": 6,
          "y": 1,
          "z": 10,
          "color": "#5f6f38"
        },
        {
          "x": 7,
          "y": 1,
          "z": 10,
          "color": "#1b2418"
        },
        {
          "x": 8,
          "y": 1,
          "z": 10,
          "color": "#5f6f38"
        },
        {
          "x": 9,
          "y": 1,
          "z": 10,
          "color": "#5f6f38"
        },
        {
          "x": 10,
          "y": 1,
          "z": 10,
          "color": "#5f6f38"
        },
        {
          "x": 11,
          "y": 1,
          "z": 10,
          "color": "#1a120f"
        },
        {
          "x": 5,
          "y": -2,
          "z": 11,
          "color": "#5f6f38"
        },
        {
          "x": 6,
          "y": -2,
          "z": 11,
          "color": "#5f6f38"
        },
        {
          "x": 7,
          "y": -2,
          "z": 11,
          "color": "#5f6f38"
        },
        {
          "x": 8,
          "y": -2,
          "z": 11,
          "color": "#9b3f46"
        },
        {
          "x": 9,
          "y": -2,
          "z": 11,
          "color": "#f4f4e8"
        },
        {
          "x": 10,
          "y": -2,
          "z": 11,
          "color": "#f4f4e8"
        },
        {
          "x": 11,
          "y": -2,
          "z": 11,
          "color": "#5f6f38"
        },
        {
          "x": 5,
          "y": -1,
          "z": 11,
          "color": "#5f6f38"
        },
        {
          "x": 6,
          "y": -1,
          "z": 11,
          "color": "#5f6f38"
        },
        {
          "x": 7,
          "y": -1,
          "z": 11,
          "color": "#5f6f38"
        },
        {
          "x": 8,
          "y": -1,
          "z": 11,
          "color": "#5f6f38"
        },
        {
          "x": 9,
          "y": -1,
          "z": 11,
          "color": "#5f6f38"
        },
        {
          "x": 10,
          "y": -1,
          "z": 11,
          "color": "#5f6f38"
        },
        {
          "x": 11,
          "y": -1,
          "z": 11,
          "color": "#5f6f38"
        },
        {
          "x": 5,
          "y": 0,
          "z": 11,
          "color": "#5f6f38"
        },
        {
          "x": 6,
          "y": 0,
          "z": 11,
          "color": "#5f6f38"
        },
        {
          "x": 7,
          "y": 0,
          "z": 11,
          "color": "#5f6f38"
        },
        {
          "x": 8,
          "y": 0,
          "z": 11,
          "color": "#5f6f38"
        },
        {
          "x": 9,
          "y": 0,
          "z": 11,
          "color": "#5f6f38"
        },
        {
          "x": 10,
          "y": 0,
          "z": 11,
          "color": "#5f6f38"
        },
        {
          "x": 11,
          "y": 0,
          "z": 11,
          "color": "#5f6f38"
        },
        {
          "x": 5,
          "y": 1,
          "z": 11,
          "color": "#5f6f38"
        },
        {
          "x": 6,
          "y": 1,
          "z": 11,
          "color": "#5f6f38"
        },
        {
          "x": 7,
          "y": 1,
          "z": 11,
          "color": "#5f6f38"
        },
        {
          "x": 8,
          "y": 1,
          "z": 11,
          "color": "#5f6f38"
        },
        {
          "x": 9,
          "y": 1,
          "z": 11,
          "color": "#5f6f38"
        },
        {
          "x": 10,
          "y": 1,
          "z": 11,
          "color": "#f4f4e8"
        },
        {
          "x": 11,
          "y": 1,
          "z": 11,
          "color": "#f4f4e8"
        },
        {
          "x": 5,
          "y": -2,
          "z": 12,
          "color": "#5f6f38"
        },
        {
          "x": 6,
          "y": -2,
          "z": 12,
          "color": "#5f6f38"
        },
        {
          "x": 7,
          "y": -2,
          "z": 12,
          "color": "#5f6f38"
        },
        {
          "x": 8,
          "y": -2,
          "z": 12,
          "color": "#5f6f38"
        },
        {
          "x": 9,
          "y": -2,
          "z": 12,
          "color": "#5f6f38"
        },
        {
          "x": 10,
          "y": -2,
          "z": 12,
          "color": "#5f6f38"
        },
        {
          "x": 11,
          "y": -2,
          "z": 12,
          "color": "#26311f"
        },
        {
          "x": 5,
          "y": -1,
          "z": 12,
          "color": "#5f6f38"
        },
        {
          "x": 6,
          "y": -1,
          "z": 12,
          "color": "#5f6f38"
        },
        {
          "x": 7,
          "y": -1,
          "z": 12,
          "color": "#5f6f38"
        },
        {
          "x": 8,
          "y": -1,
          "z": 12,
          "color": "#5f6f38"
        },
        {
          "x": 9,
          "y": -1,
          "z": 12,
          "color": "#5f6f38"
        },
        {
          "x": 10,
          "y": -1,
          "z": 12,
          "color": "#5f6f38"
        },
        {
          "x": 5,
          "y": 0,
          "z": 12,
          "color": "#5f6f38"
        },
        {
          "x": 6,
          "y": 0,
          "z": 12,
          "color": "#5f6f38"
        },
        {
          "x": 7,
          "y": 0,
          "z": 12,
          "color": "#5f6f38"
        },
        {
          "x": 8,
          "y": 0,
          "z": 12,
          "color": "#5f6f38"
        },
        {
          "x": 9,
          "y": 0,
          "z": 12,
          "color": "#5f6f38"
        },
        {
          "x": 10,
          "y": 0,
          "z": 12,
          "color": "#5f6f38"
        },
        {
          "x": 5,
          "y": 1,
          "z": 12,
          "color": "#5f6f38"
        },
        {
          "x": 6,
          "y": 1,
          "z": 12,
          "color": "#5f6f38"
        },
        {
          "x": 7,
          "y": 1,
          "z": 12,
          "color": "#5f6f38"
        },
        {
          "x": 8,
          "y": 1,
          "z": 12,
          "color": "#5f6f38"
        },
        {
          "x": 9,
          "y": 1,
          "z": 12,
          "color": "#5f6f38"
        },
        {
          "x": 10,
          "y": 1,
          "z": 12,
          "color": "#26311f"
        },
        {
          "x": 5,
          "y": -2,
          "z": 13,
          "color": "#26311f"
        },
        {
          "x": 6,
          "y": -2,
          "z": 13,
          "color": "#5f6f38"
        },
        {
          "x": 7,
          "y": -2,
          "z": 13,
          "color": "#5f6f38"
        },
        {
          "x": 8,
          "y": -2,
          "z": 13,
          "color": "#718249"
        },
        {
          "x": 9,
          "y": -2,
          "z": 13,
          "color": "#26311f"
        },
        {
          "x": 5,
          "y": -1,
          "z": 13,
          "color": "#5f6f38"
        },
        {
          "x": 6,
          "y": -1,
          "z": 13,
          "color": "#5f6f38"
        },
        {
          "x": 7,
          "y": -1,
          "z": 13,
          "color": "#5f6f38"
        },
        {
          "x": 8,
          "y": -1,
          "z": 13,
          "color": "#718249"
        },
        {
          "x": 9,
          "y": -1,
          "z": 13,
          "color": "#718249"
        },
        {
          "x": 5,
          "y": 0,
          "z": 13,
          "color": "#5f6f38"
        },
        {
          "x": 6,
          "y": 0,
          "z": 13,
          "color": "#5f6f38"
        },
        {
          "x": 7,
          "y": 0,
          "z": 13,
          "color": "#5f6f38"
        },
        {
          "x": 8,
          "y": 0,
          "z": 13,
          "color": "#718249"
        },
        {
          "x": 9,
          "y": 0,
          "z": 13,
          "color": "#718249"
        },
        {
          "x": 5,
          "y": 1,
          "z": 13,
          "color": "#5f6f38"
        },
        {
          "x": 6,
          "y": 1,
          "z": 13,
          "color": "#5f6f38"
        },
        {
          "x": 7,
          "y": 1,
          "z": 13,
          "color": "#5f6f38"
        },
        {
          "x": 8,
          "y": 1,
          "z": 13,
          "color": "#718249"
        },
        {
          "x": 9,
          "y": 1,
          "z": 13,
          "color": "#718249"
        },
        {
          "x": 6,
          "y": -2,
          "z": 14,
          "color": "#718249"
        },
        {
          "x": 7,
          "y": -2,
          "z": 14,
          "color": "#718249"
        },
        {
          "x": 6,
          "y": -1,
          "z": 14,
          "color": "#718249"
        },
        {
          "x": 7,
          "y": -1,
          "z": 14,
          "color": "#718249"
        },
        {
          "x": 6,
          "y": 0,
          "z": 14,
          "color": "#718249"
        },
        {
          "x": 7,
          "y": 0,
          "z": 14,
          "color": "#718249"
        },
        {
          "x": 6,
          "y": 1,
          "z": 14,
          "color": "#718249"
        },
        {
          "x": 7,
          "y": 1,
          "z": 14,
          "color": "#718249"
        }
      ],
      "baseRotation": {
        "x": 0,
        "y": 0,
        "z": 0
      },
      "dynamic": false
    },
    "water": {
      "voxelSize": 3,
      "voxels": [
        {
          "x": -3,
          "y": -1,
          "z": -1,
          "color": "#eefbff"
        },
        {
          "x": -2,
          "y": -1,
          "z": -1,
          "color": "#eefbff"
        },
        {
          "x": -1,
          "y": -1,
          "z": -1,
          "color": "#eefbff"
        },
        {
          "x": 0,
          "y": -1,
          "z": -1,
          "color": "#eefbff"
        },
        {
          "x": 1,
          "y": -1,
          "z": -1,
          "color": "#eefbff"
        },
        {
          "x": 2,
          "y": -1,
          "z": -1,
          "color": "#eefbff"
        },
        {
          "x": -3,
          "y": 0,
          "z": -1,
          "color": "#eefbff"
        },
        {
          "x": -2,
          "y": 0,
          "z": -1,
          "color": "#eefbff"
        },
        {
          "x": 0,
          "y": 0,
          "z": -1,
          "color": "#eefbff"
        },
        {
          "x": 1,
          "y": 0,
          "z": -1,
          "color": "#eefbff"
        },
        {
          "x": -3,
          "y": -1,
          "z": 0,
          "color": "#0d2436"
        },
        {
          "x": -2,
          "y": -1,
          "z": 0,
          "color": "#0d2436"
        },
        {
          "x": 0,
          "y": -1,
          "z": 0,
          "color": "#0d2436"
        },
        {
          "x": 1,
          "y": -1,
          "z": 0,
          "color": "#0d2436"
        },
        {
          "x": -3,
          "y": 0,
          "z": 0,
          "color": "#0d2436"
        },
        {
          "x": -2,
          "y": 0,
          "z": 0,
          "color": "#0d2436"
        },
        {
          "x": 0,
          "y": 0,
          "z": 0,
          "color": "#0d2436"
        },
        {
          "x": 1,
          "y": 0,
          "z": 0,
          "color": "#0d2436"
        },
        {
          "x": -3,
          "y": -1,
          "z": 1,
          "color": "#0d2436"
        },
        {
          "x": -2,
          "y": -1,
          "z": 1,
          "color": "#0d2436"
        },
        {
          "x": 0,
          "y": -1,
          "z": 1,
          "color": "#0d2436"
        },
        {
          "x": 1,
          "y": -1,
          "z": 1,
          "color": "#0d2436"
        },
        {
          "x": -3,
          "y": 0,
          "z": 1,
          "color": "#0d2436"
        },
        {
          "x": -2,
          "y": 0,
          "z": 1,
          "color": "#0d2436"
        },
        {
          "x": 0,
          "y": 0,
          "z": 1,
          "color": "#0d2436"
        },
        {
          "x": 1,
          "y": 0,
          "z": 1,
          "color": "#0d2436"
        },
        {
          "x": -11,
          "y": -1,
          "z": 2,
          "color": "#0d2436"
        },
        {
          "x": -3,
          "y": -1,
          "z": 2,
          "color": "#0d2436"
        },
        {
          "x": -2,
          "y": -1,
          "z": 2,
          "color": "#0d2436"
        },
        {
          "x": 0,
          "y": -1,
          "z": 2,
          "color": "#0d2436"
        },
        {
          "x": 1,
          "y": -1,
          "z": 2,
          "color": "#0d2436"
        },
        {
          "x": -9,
          "y": 0,
          "z": 2,
          "color": "#0d2436"
        },
        {
          "x": -3,
          "y": 0,
          "z": 2,
          "color": "#0d2436"
        },
        {
          "x": -2,
          "y": 0,
          "z": 2,
          "color": "#0d2436"
        },
        {
          "x": 0,
          "y": 0,
          "z": 2,
          "color": "#0d2436"
        },
        {
          "x": 1,
          "y": 0,
          "z": 2,
          "color": "#0d2436"
        },
        {
          "x": 2,
          "y": -2,
          "z": 3,
          "color": "#eefbff"
        },
        {
          "x": -11,
          "y": -1,
          "z": 3,
          "color": "#347fb1"
        },
        {
          "x": -10,
          "y": -1,
          "z": 3,
          "color": "#347fb1"
        },
        {
          "x": -9,
          "y": -1,
          "z": 3,
          "color": "#347fb1"
        },
        {
          "x": -8,
          "y": -1,
          "z": 3,
          "color": "#347fb1"
        },
        {
          "x": -7,
          "y": -1,
          "z": 3,
          "color": "#347fb1"
        },
        {
          "x": -3,
          "y": -1,
          "z": 3,
          "color": "#0d2436"
        },
        {
          "x": -2,
          "y": -1,
          "z": 3,
          "color": "#0d2436"
        },
        {
          "x": -1,
          "y": -1,
          "z": 3,
          "color": "#bfe9ff"
        },
        {
          "x": 0,
          "y": -1,
          "z": 3,
          "color": "#0d2436"
        },
        {
          "x": 1,
          "y": -1,
          "z": 3,
          "color": "#0d2436"
        },
        {
          "x": -11,
          "y": 0,
          "z": 3,
          "color": "#347fb1"
        },
        {
          "x": -10,
          "y": 0,
          "z": 3,
          "color": "#347fb1"
        },
        {
          "x": -9,
          "y": 0,
          "z": 3,
          "color": "#347fb1"
        },
        {
          "x": -8,
          "y": 0,
          "z": 3,
          "color": "#347fb1"
        },
        {
          "x": -7,
          "y": 0,
          "z": 3,
          "color": "#347fb1"
        },
        {
          "x": -3,
          "y": 0,
          "z": 3,
          "color": "#0d2436"
        },
        {
          "x": -2,
          "y": 0,
          "z": 3,
          "color": "#0d2436"
        },
        {
          "x": -1,
          "y": 0,
          "z": 3,
          "color": "#bfe9ff"
        },
        {
          "x": 0,
          "y": 0,
          "z": 3,
          "color": "#0d2436"
        },
        {
          "x": 1,
          "y": 0,
          "z": 3,
          "color": "#0d2436"
        },
        {
          "x": 2,
          "y": 1,
          "z": 3,
          "color": "#eefbff"
        },
        {
          "x": 1,
          "y": -2,
          "z": 4,
          "color": "#347fb1"
        },
        {
          "x": 2,
          "y": -2,
          "z": 4,
          "color": "#347fb1"
        },
        {
          "x": -10,
          "y": -1,
          "z": 4,
          "color": "#17415e"
        },
        {
          "x": -8,
          "y": -1,
          "z": 4,
          "color": "#347fb1"
        },
        {
          "x": -7,
          "y": -1,
          "z": 4,
          "color": "#347fb1"
        },
        {
          "x": -6,
          "y": -1,
          "z": 4,
          "color": "#347fb1"
        },
        {
          "x": -5,
          "y": -1,
          "z": 4,
          "color": "#347fb1"
        },
        {
          "x": -4,
          "y": -1,
          "z": 4,
          "color": "#347fb1"
        },
        {
          "x": -3,
          "y": -1,
          "z": 4,
          "color": "#347fb1"
        },
        {
          "x": -2,
          "y": -1,
          "z": 4,
          "color": "#347fb1"
        },
        {
          "x": -1,
          "y": -1,
          "z": 4,
          "color": "#347fb1"
        },
        {
          "x": 0,
          "y": -1,
          "z": 4,
          "color": "#347fb1"
        },
        {
          "x": 1,
          "y": -1,
          "z": 4,
          "color": "#347fb1"
        },
        {
          "x": -8,
          "y": 0,
          "z": 4,
          "color": "#347fb1"
        },
        {
          "x": -7,
          "y": 0,
          "z": 4,
          "color": "#347fb1"
        },
        {
          "x": -6,
          "y": 0,
          "z": 4,
          "color": "#347fb1"
        },
        {
          "x": -5,
          "y": 0,
          "z": 4,
          "color": "#347fb1"
        },
        {
          "x": -4,
          "y": 0,
          "z": 4,
          "color": "#0d2436"
        },
        {
          "x": -3,
          "y": 0,
          "z": 4,
          "color": "#347fb1"
        },
        {
          "x": -2,
          "y": 0,
          "z": 4,
          "color": "#347fb1"
        },
        {
          "x": -1,
          "y": 0,
          "z": 4,
          "color": "#347fb1"
        },
        {
          "x": 0,
          "y": 0,
          "z": 4,
          "color": "#347fb1"
        },
        {
          "x": 1,
          "y": 0,
          "z": 4,
          "color": "#347fb1"
        },
        {
          "x": 1,
          "y": 1,
          "z": 4,
          "color": "#347fb1"
        },
        {
          "x": 2,
          "y": 1,
          "z": 4,
          "color": "#347fb1"
        },
        {
          "x": 1,
          "y": -2,
          "z": 5,
          "color": "#347fb1"
        },
        {
          "x": 2,
          "y": -2,
          "z": 5,
          "color": "#347fb1"
        },
        {
          "x": -6,
          "y": -1,
          "z": 5,
          "color": "#347fb1"
        },
        {
          "x": -5,
          "y": -1,
          "z": 5,
          "color": "#347fb1"
        },
        {
          "x": -4,
          "y": -1,
          "z": 5,
          "color": "#0d2436"
        },
        {
          "x": -3,
          "y": -1,
          "z": 5,
          "color": "#347fb1"
        },
        {
          "x": -2,
          "y": -1,
          "z": 5,
          "color": "#347fb1"
        },
        {
          "x": -1,
          "y": -1,
          "z": 5,
          "color": "#347fb1"
        },
        {
          "x": 0,
          "y": -1,
          "z": 5,
          "color": "#347fb1"
        },
        {
          "x": 1,
          "y": -1,
          "z": 5,
          "color": "#347fb1"
        },
        {
          "x": 2,
          "y": -1,
          "z": 5,
          "color": "#347fb1"
        },
        {
          "x": -8,
          "y": 0,
          "z": 5,
          "color": "#17415e"
        },
        {
          "x": -6,
          "y": 0,
          "z": 5,
          "color": "#347fb1"
        },
        {
          "x": -5,
          "y": 0,
          "z": 5,
          "color": "#347fb1"
        },
        {
          "x": -4,
          "y": 0,
          "z": 5,
          "color": "#347fb1"
        },
        {
          "x": -3,
          "y": 0,
          "z": 5,
          "color": "#347fb1"
        },
        {
          "x": -2,
          "y": 0,
          "z": 5,
          "color": "#347fb1"
        },
        {
          "x": -1,
          "y": 0,
          "z": 5,
          "color": "#347fb1"
        },
        {
          "x": 0,
          "y": 0,
          "z": 5,
          "color": "#347fb1"
        },
        {
          "x": 1,
          "y": 0,
          "z": 5,
          "color": "#347fb1"
        },
        {
          "x": 2,
          "y": 0,
          "z": 5,
          "color": "#0d2436"
        },
        {
          "x": 1,
          "y": 1,
          "z": 5,
          "color": "#347fb1"
        },
        {
          "x": 2,
          "y": 1,
          "z": 5,
          "color": "#347fb1"
        },
        {
          "x": -6,
          "y": -1,
          "z": 6,
          "color": "#17415e"
        },
        {
          "x": -4,
          "y": -1,
          "z": 6,
          "color": "#347fb1"
        },
        {
          "x": -3,
          "y": -1,
          "z": 6,
          "color": "#347fb1"
        },
        {
          "x": -2,
          "y": -1,
          "z": 6,
          "color": "#347fb1"
        },
        {
          "x": -1,
          "y": -1,
          "z": 6,
          "color": "#347fb1"
        },
        {
          "x": 0,
          "y": -1,
          "z": 6,
          "color": "#347fb1"
        },
        {
          "x": 1,
          "y": -1,
          "z": 6,
          "color": "#347fb1"
        },
        {
          "x": 2,
          "y": -1,
          "z": 6,
          "color": "#347fb1"
        },
        {
          "x": -4,
          "y": 0,
          "z": 6,
          "color": "#347fb1"
        },
        {
          "x": -3,
          "y": 0,
          "z": 6,
          "color": "#347fb1"
        },
        {
          "x": -2,
          "y": 0,
          "z": 6,
          "color": "#347fb1"
        },
        {
          "x": -1,
          "y": 0,
          "z": 6,
          "color": "#347fb1"
        },
        {
          "x": 0,
          "y": 0,
          "z": 6,
          "color": "#347fb1"
        },
        {
          "x": 1,
          "y": 0,
          "z": 6,
          "color": "#347fb1"
        },
        {
          "x": 2,
          "y": 0,
          "z": 6,
          "color": "#347fb1"
        },
        {
          "x": -3,
          "y": -1,
          "z": 7,
          "color": "#17415e"
        },
        {
          "x": -2,
          "y": -1,
          "z": 7,
          "color": "#57aee0"
        },
        {
          "x": -1,
          "y": -1,
          "z": 7,
          "color": "#57aee0"
        },
        {
          "x": 0,
          "y": -1,
          "z": 7,
          "color": "#57aee0"
        },
        {
          "x": 1,
          "y": -1,
          "z": 7,
          "color": "#17415e"
        },
        {
          "x": 2,
          "y": -1,
          "z": 7,
          "color": "#347fb1"
        },
        {
          "x": 3,
          "y": -1,
          "z": 7,
          "color": "#0d2436"
        },
        {
          "x": -2,
          "y": 0,
          "z": 7,
          "color": "#57aee0"
        },
        {
          "x": -1,
          "y": 0,
          "z": 7,
          "color": "#57aee0"
        },
        {
          "x": 0,
          "y": 0,
          "z": 7,
          "color": "#57aee0"
        },
        {
          "x": 1,
          "y": 0,
          "z": 7,
          "color": "#57aee0"
        },
        {
          "x": 2,
          "y": 0,
          "z": 7,
          "color": "#347fb1"
        },
        {
          "x": 3,
          "y": 0,
          "z": 7,
          "color": "#0d2436"
        },
        {
          "x": 8,
          "y": -2,
          "z": 8,
          "color": "#0d2436"
        },
        {
          "x": 9,
          "y": -2,
          "z": 8,
          "color": "#0d2436"
        },
        {
          "x": 10,
          "y": -2,
          "z": 8,
          "color": "#0d2436"
        },
        {
          "x": 11,
          "y": -2,
          "z": 8,
          "color": "#0d2436"
        },
        {
          "x": 2,
          "y": -1,
          "z": 8,
          "color": "#347fb1"
        },
        {
          "x": 3,
          "y": -1,
          "z": 8,
          "color": "#347fb1"
        },
        {
          "x": 4,
          "y": -1,
          "z": 8,
          "color": "#0d2436"
        },
        {
          "x": 8,
          "y": -1,
          "z": 8,
          "color": "#0d2436"
        },
        {
          "x": 9,
          "y": -1,
          "z": 8,
          "color": "#0d2436"
        },
        {
          "x": 10,
          "y": -1,
          "z": 8,
          "color": "#0d2436"
        },
        {
          "x": 11,
          "y": -1,
          "z": 8,
          "color": "#0d2436"
        },
        {
          "x": -1,
          "y": 0,
          "z": 8,
          "color": "#17415e"
        },
        {
          "x": 2,
          "y": 0,
          "z": 8,
          "color": "#347fb1"
        },
        {
          "x": 3,
          "y": 0,
          "z": 8,
          "color": "#347fb1"
        },
        {
          "x": 4,
          "y": 0,
          "z": 8,
          "color": "#0d2436"
        },
        {
          "x": 8,
          "y": 0,
          "z": 8,
          "color": "#0d2436"
        },
        {
          "x": 9,
          "y": 0,
          "z": 8,
          "color": "#0d2436"
        },
        {
          "x": 10,
          "y": 0,
          "z": 8,
          "color": "#0d2436"
        },
        {
          "x": 11,
          "y": 0,
          "z": 8,
          "color": "#0d2436"
        },
        {
          "x": 8,
          "y": 1,
          "z": 8,
          "color": "#0d2436"
        },
        {
          "x": 9,
          "y": 1,
          "z": 8,
          "color": "#0d2436"
        },
        {
          "x": 10,
          "y": 1,
          "z": 8,
          "color": "#0d2436"
        },
        {
          "x": 11,
          "y": 1,
          "z": 8,
          "color": "#0d2436"
        },
        {
          "x": 8,
          "y": -2,
          "z": 9,
          "color": "#347fb1"
        },
        {
          "x": 9,
          "y": -2,
          "z": 9,
          "color": "#347fb1"
        },
        {
          "x": 10,
          "y": -2,
          "z": 9,
          "color": "#347fb1"
        },
        {
          "x": 11,
          "y": -2,
          "z": 9,
          "color": "#081018"
        },
        {
          "x": 3,
          "y": -1,
          "z": 9,
          "color": "#347fb1"
        },
        {
          "x": 4,
          "y": -1,
          "z": 9,
          "color": "#347fb1"
        },
        {
          "x": 8,
          "y": -1,
          "z": 9,
          "color": "#347fb1"
        },
        {
          "x": 9,
          "y": -1,
          "z": 9,
          "color": "#347fb1"
        },
        {
          "x": 10,
          "y": -1,
          "z": 9,
          "color": "#347fb1"
        },
        {
          "x": 11,
          "y": -1,
          "z": 9,
          "color": "#347fb1"
        },
        {
          "x": 3,
          "y": 0,
          "z": 9,
          "color": "#347fb1"
        },
        {
          "x": 4,
          "y": 0,
          "z": 9,
          "color": "#347fb1"
        },
        {
          "x": 8,
          "y": 0,
          "z": 9,
          "color": "#347fb1"
        },
        {
          "x": 9,
          "y": 0,
          "z": 9,
          "color": "#347fb1"
        },
        {
          "x": 10,
          "y": 0,
          "z": 9,
          "color": "#347fb1"
        },
        {
          "x": 11,
          "y": 0,
          "z": 9,
          "color": "#347fb1"
        },
        {
          "x": 8,
          "y": 1,
          "z": 9,
          "color": "#0d2436"
        },
        {
          "x": 9,
          "y": 1,
          "z": 9,
          "color": "#347fb1"
        },
        {
          "x": 10,
          "y": 1,
          "z": 9,
          "color": "#347fb1"
        },
        {
          "x": 11,
          "y": 1,
          "z": 9,
          "color": "#081018"
        },
        {
          "x": 5,
          "y": -2,
          "z": 10,
          "color": "#347fb1"
        },
        {
          "x": 6,
          "y": -2,
          "z": 10,
          "color": "#347fb1"
        },
        {
          "x": 7,
          "y": -2,
          "z": 10,
          "color": "#347fb1"
        },
        {
          "x": 8,
          "y": -2,
          "z": 10,
          "color": "#347fb1"
        },
        {
          "x": 9,
          "y": -2,
          "z": 10,
          "color": "#347fb1"
        },
        {
          "x": 10,
          "y": -2,
          "z": 10,
          "color": "#081018"
        },
        {
          "x": 11,
          "y": -2,
          "z": 10,
          "color": "#347fb1"
        },
        {
          "x": 4,
          "y": -1,
          "z": 10,
          "color": "#347fb1"
        },
        {
          "x": 5,
          "y": -1,
          "z": 10,
          "color": "#347fb1"
        },
        {
          "x": 6,
          "y": -1,
          "z": 10,
          "color": "#347fb1"
        },
        {
          "x": 7,
          "y": -1,
          "z": 10,
          "color": "#347fb1"
        },
        {
          "x": 8,
          "y": -1,
          "z": 10,
          "color": "#347fb1"
        },
        {
          "x": 9,
          "y": -1,
          "z": 10,
          "color": "#347fb1"
        },
        {
          "x": 10,
          "y": -1,
          "z": 10,
          "color": "#347fb1"
        },
        {
          "x": 11,
          "y": -1,
          "z": 10,
          "color": "#347fb1"
        },
        {
          "x": 4,
          "y": 0,
          "z": 10,
          "color": "#347fb1"
        },
        {
          "x": 5,
          "y": 0,
          "z": 10,
          "color": "#347fb1"
        },
        {
          "x": 6,
          "y": 0,
          "z": 10,
          "color": "#347fb1"
        },
        {
          "x": 7,
          "y": 0,
          "z": 10,
          "color": "#347fb1"
        },
        {
          "x": 8,
          "y": 0,
          "z": 10,
          "color": "#347fb1"
        },
        {
          "x": 9,
          "y": 0,
          "z": 10,
          "color": "#347fb1"
        },
        {
          "x": 10,
          "y": 0,
          "z": 10,
          "color": "#347fb1"
        },
        {
          "x": 11,
          "y": 0,
          "z": 10,
          "color": "#347fb1"
        },
        {
          "x": 5,
          "y": 1,
          "z": 10,
          "color": "#347fb1"
        },
        {
          "x": 6,
          "y": 1,
          "z": 10,
          "color": "#347fb1"
        },
        {
          "x": 7,
          "y": 1,
          "z": 10,
          "color": "#0d2436"
        },
        {
          "x": 8,
          "y": 1,
          "z": 10,
          "color": "#347fb1"
        },
        {
          "x": 9,
          "y": 1,
          "z": 10,
          "color": "#347fb1"
        },
        {
          "x": 10,
          "y": 1,
          "z": 10,
          "color": "#347fb1"
        },
        {
          "x": 11,
          "y": 1,
          "z": 10,
          "color": "#081018"
        },
        {
          "x": 5,
          "y": -2,
          "z": 11,
          "color": "#347fb1"
        },
        {
          "x": 6,
          "y": -2,
          "z": 11,
          "color": "#347fb1"
        },
        {
          "x": 7,
          "y": -2,
          "z": 11,
          "color": "#347fb1"
        },
        {
          "x": 8,
          "y": -2,
          "z": 11,
          "color": "#55d4ff"
        },
        {
          "x": 9,
          "y": -2,
          "z": 11,
          "color": "#f8fdff"
        },
        {
          "x": 10,
          "y": -2,
          "z": 11,
          "color": "#f8fdff"
        },
        {
          "x": 11,
          "y": -2,
          "z": 11,
          "color": "#347fb1"
        },
        {
          "x": 5,
          "y": -1,
          "z": 11,
          "color": "#347fb1"
        },
        {
          "x": 6,
          "y": -1,
          "z": 11,
          "color": "#347fb1"
        },
        {
          "x": 7,
          "y": -1,
          "z": 11,
          "color": "#347fb1"
        },
        {
          "x": 8,
          "y": -1,
          "z": 11,
          "color": "#347fb1"
        },
        {
          "x": 9,
          "y": -1,
          "z": 11,
          "color": "#347fb1"
        },
        {
          "x": 10,
          "y": -1,
          "z": 11,
          "color": "#347fb1"
        },
        {
          "x": 11,
          "y": -1,
          "z": 11,
          "color": "#347fb1"
        },
        {
          "x": 5,
          "y": 0,
          "z": 11,
          "color": "#347fb1"
        },
        {
          "x": 6,
          "y": 0,
          "z": 11,
          "color": "#347fb1"
        },
        {
          "x": 7,
          "y": 0,
          "z": 11,
          "color": "#347fb1"
        },
        {
          "x": 8,
          "y": 0,
          "z": 11,
          "color": "#347fb1"
        },
        {
          "x": 9,
          "y": 0,
          "z": 11,
          "color": "#347fb1"
        },
        {
          "x": 10,
          "y": 0,
          "z": 11,
          "color": "#347fb1"
        },
        {
          "x": 11,
          "y": 0,
          "z": 11,
          "color": "#347fb1"
        },
        {
          "x": 5,
          "y": 1,
          "z": 11,
          "color": "#347fb1"
        },
        {
          "x": 6,
          "y": 1,
          "z": 11,
          "color": "#347fb1"
        },
        {
          "x": 7,
          "y": 1,
          "z": 11,
          "color": "#347fb1"
        },
        {
          "x": 8,
          "y": 1,
          "z": 11,
          "color": "#347fb1"
        },
        {
          "x": 9,
          "y": 1,
          "z": 11,
          "color": "#347fb1"
        },
        {
          "x": 10,
          "y": 1,
          "z": 11,
          "color": "#f8fdff"
        },
        {
          "x": 11,
          "y": 1,
          "z": 11,
          "color": "#f8fdff"
        },
        {
          "x": 5,
          "y": -2,
          "z": 12,
          "color": "#347fb1"
        },
        {
          "x": 6,
          "y": -2,
          "z": 12,
          "color": "#347fb1"
        },
        {
          "x": 7,
          "y": -2,
          "z": 12,
          "color": "#347fb1"
        },
        {
          "x": 8,
          "y": -2,
          "z": 12,
          "color": "#347fb1"
        },
        {
          "x": 9,
          "y": -2,
          "z": 12,
          "color": "#347fb1"
        },
        {
          "x": 10,
          "y": -2,
          "z": 12,
          "color": "#347fb1"
        },
        {
          "x": 11,
          "y": -2,
          "z": 12,
          "color": "#17415e"
        },
        {
          "x": 5,
          "y": -1,
          "z": 12,
          "color": "#347fb1"
        },
        {
          "x": 6,
          "y": -1,
          "z": 12,
          "color": "#347fb1"
        },
        {
          "x": 7,
          "y": -1,
          "z": 12,
          "color": "#347fb1"
        },
        {
          "x": 8,
          "y": -1,
          "z": 12,
          "color": "#347fb1"
        },
        {
          "x": 9,
          "y": -1,
          "z": 12,
          "color": "#347fb1"
        },
        {
          "x": 10,
          "y": -1,
          "z": 12,
          "color": "#347fb1"
        },
        {
          "x": 5,
          "y": 0,
          "z": 12,
          "color": "#347fb1"
        },
        {
          "x": 6,
          "y": 0,
          "z": 12,
          "color": "#347fb1"
        },
        {
          "x": 7,
          "y": 0,
          "z": 12,
          "color": "#347fb1"
        },
        {
          "x": 8,
          "y": 0,
          "z": 12,
          "color": "#347fb1"
        },
        {
          "x": 9,
          "y": 0,
          "z": 12,
          "color": "#347fb1"
        },
        {
          "x": 10,
          "y": 0,
          "z": 12,
          "color": "#347fb1"
        },
        {
          "x": 5,
          "y": 1,
          "z": 12,
          "color": "#347fb1"
        },
        {
          "x": 6,
          "y": 1,
          "z": 12,
          "color": "#347fb1"
        },
        {
          "x": 7,
          "y": 1,
          "z": 12,
          "color": "#347fb1"
        },
        {
          "x": 8,
          "y": 1,
          "z": 12,
          "color": "#347fb1"
        },
        {
          "x": 9,
          "y": 1,
          "z": 12,
          "color": "#347fb1"
        },
        {
          "x": 10,
          "y": 1,
          "z": 12,
          "color": "#17415e"
        },
        {
          "x": 5,
          "y": -2,
          "z": 13,
          "color": "#17415e"
        },
        {
          "x": 6,
          "y": -2,
          "z": 13,
          "color": "#347fb1"
        },
        {
          "x": 7,
          "y": -2,
          "z": 13,
          "color": "#347fb1"
        },
        {
          "x": 8,
          "y": -2,
          "z": 13,
          "color": "#57aee0"
        },
        {
          "x": 9,
          "y": -2,
          "z": 13,
          "color": "#17415e"
        },
        {
          "x": 5,
          "y": -1,
          "z": 13,
          "color": "#347fb1"
        },
        {
          "x": 6,
          "y": -1,
          "z": 13,
          "color": "#347fb1"
        },
        {
          "x": 7,
          "y": -1,
          "z": 13,
          "color": "#347fb1"
        },
        {
          "x": 8,
          "y": -1,
          "z": 13,
          "color": "#57aee0"
        },
        {
          "x": 9,
          "y": -1,
          "z": 13,
          "color": "#57aee0"
        },
        {
          "x": 5,
          "y": 0,
          "z": 13,
          "color": "#347fb1"
        },
        {
          "x": 6,
          "y": 0,
          "z": 13,
          "color": "#347fb1"
        },
        {
          "x": 7,
          "y": 0,
          "z": 13,
          "color": "#347fb1"
        },
        {
          "x": 8,
          "y": 0,
          "z": 13,
          "color": "#57aee0"
        },
        {
          "x": 9,
          "y": 0,
          "z": 13,
          "color": "#57aee0"
        },
        {
          "x": 5,
          "y": 1,
          "z": 13,
          "color": "#347fb1"
        },
        {
          "x": 6,
          "y": 1,
          "z": 13,
          "color": "#347fb1"
        },
        {
          "x": 7,
          "y": 1,
          "z": 13,
          "color": "#347fb1"
        },
        {
          "x": 8,
          "y": 1,
          "z": 13,
          "color": "#57aee0"
        },
        {
          "x": 9,
          "y": 1,
          "z": 13,
          "color": "#57aee0"
        },
        {
          "x": 6,
          "y": -2,
          "z": 14,
          "color": "#57aee0"
        },
        {
          "x": 7,
          "y": -2,
          "z": 14,
          "color": "#57aee0"
        },
        {
          "x": 6,
          "y": -1,
          "z": 14,
          "color": "#57aee0"
        },
        {
          "x": 7,
          "y": -1,
          "z": 14,
          "color": "#57aee0"
        },
        {
          "x": 6,
          "y": 0,
          "z": 14,
          "color": "#57aee0"
        },
        {
          "x": 7,
          "y": 0,
          "z": 14,
          "color": "#57aee0"
        },
        {
          "x": 6,
          "y": 1,
          "z": 14,
          "color": "#57aee0"
        },
        {
          "x": 7,
          "y": 1,
          "z": 14,
          "color": "#57aee0"
        }
      ],
      "baseRotation": {
        "x": 0,
        "y": 0,
        "z": 0
      },
      "dynamic": false
    },
    "ptero": {
      "voxelSize": 3,
      "voxels": [
        {
          "x": -4,
          "y": -1,
          "z": -3,
          "color": "#ddd6c8"
        },
        {
          "x": -3,
          "y": -1,
          "z": -3,
          "color": "#ddd6c8"
        },
        {
          "x": -2,
          "y": 0,
          "z": -3,
          "color": "#ddd6c8"
        },
        {
          "x": -1,
          "y": 0,
          "z": -3,
          "color": "#ddd6c8"
        },
        {
          "x": -13,
          "y": -16,
          "z": -2,
          "color": "#ddd6c8"
        },
        {
          "x": -12,
          "y": -15,
          "z": -2,
          "color": "#2d211c"
        },
        {
          "x": -11,
          "y": -15,
          "z": -2,
          "color": "#2d211c"
        },
        {
          "x": -10,
          "y": -15,
          "z": -2,
          "color": "#2d211c"
        },
        {
          "x": -9,
          "y": -15,
          "z": -2,
          "color": "#2d211c"
        },
        {
          "x": -8,
          "y": -15,
          "z": -2,
          "color": "#2d211c"
        },
        {
          "x": -7,
          "y": -15,
          "z": -2,
          "color": "#2d211c"
        },
        {
          "x": -6,
          "y": -15,
          "z": -2,
          "color": "#2d211c"
        },
        {
          "x": -5,
          "y": -15,
          "z": -2,
          "color": "#2d211c"
        },
        {
          "x": -4,
          "y": -15,
          "z": -2,
          "color": "#2d211c"
        },
        {
          "x": -11,
          "y": -14,
          "z": -2,
          "color": "#2d211c"
        },
        {
          "x": -10,
          "y": -14,
          "z": -2,
          "color": "#2d211c"
        },
        {
          "x": -9,
          "y": -14,
          "z": -2,
          "color": "#2d211c"
        },
        {
          "x": -8,
          "y": -14,
          "z": -2,
          "color": "#2d211c"
        },
        {
          "x": -7,
          "y": -14,
          "z": -2,
          "color": "#2d211c"
        },
        {
          "x": -6,
          "y": -14,
          "z": -2,
          "color": "#2d211c"
        },
        {
          "x": -5,
          "y": -14,
          "z": -2,
          "color": "#2d211c"
        },
        {
          "x": -4,
          "y": -14,
          "z": -2,
          "color": "#2d211c"
        },
        {
          "x": -10,
          "y": -13,
          "z": -2,
          "color": "#2d211c"
        },
        {
          "x": -9,
          "y": -13,
          "z": -2,
          "color": "#2d211c"
        },
        {
          "x": -8,
          "y": -13,
          "z": -2,
          "color": "#2d211c"
        },
        {
          "x": -7,
          "y": -13,
          "z": -2,
          "color": "#2d211c"
        },
        {
          "x": -6,
          "y": -13,
          "z": -2,
          "color": "#2d211c"
        },
        {
          "x": -5,
          "y": -13,
          "z": -2,
          "color": "#2d211c"
        },
        {
          "x": -4,
          "y": -13,
          "z": -2,
          "color": "#2d211c"
        },
        {
          "x": -3,
          "y": -13,
          "z": -2,
          "color": "#2d211c"
        },
        {
          "x": -9,
          "y": -12,
          "z": -2,
          "color": "#2d211c"
        },
        {
          "x": -8,
          "y": -12,
          "z": -2,
          "color": "#2d211c"
        },
        {
          "x": -7,
          "y": -12,
          "z": -2,
          "color": "#2d211c"
        },
        {
          "x": -6,
          "y": -12,
          "z": -2,
          "color": "#2d211c"
        },
        {
          "x": -5,
          "y": -12,
          "z": -2,
          "color": "#2d211c"
        },
        {
          "x": -4,
          "y": -12,
          "z": -2,
          "color": "#2d211c"
        },
        {
          "x": -3,
          "y": -12,
          "z": -2,
          "color": "#2d211c"
        },
        {
          "x": -9,
          "y": -11,
          "z": -2,
          "color": "#2d211c"
        },
        {
          "x": -8,
          "y": -11,
          "z": -2,
          "color": "#2d211c"
        },
        {
          "x": -7,
          "y": -11,
          "z": -2,
          "color": "#2d211c"
        },
        {
          "x": -6,
          "y": -11,
          "z": -2,
          "color": "#2d211c"
        },
        {
          "x": -5,
          "y": -11,
          "z": -2,
          "color": "#2d211c"
        },
        {
          "x": -4,
          "y": -11,
          "z": -2,
          "color": "#2d211c"
        },
        {
          "x": -3,
          "y": -11,
          "z": -2,
          "color": "#2d211c"
        },
        {
          "x": -2,
          "y": -11,
          "z": -2,
          "color": "#2d211c"
        },
        {
          "x": -8,
          "y": -10,
          "z": -2,
          "color": "#2d211c"
        },
        {
          "x": -7,
          "y": -10,
          "z": -2,
          "color": "#2d211c"
        },
        {
          "x": -6,
          "y": -10,
          "z": -2,
          "color": "#b37443"
        },
        {
          "x": -5,
          "y": -10,
          "z": -2,
          "color": "#2d211c"
        },
        {
          "x": -4,
          "y": -10,
          "z": -2,
          "color": "#2d211c"
        },
        {
          "x": -3,
          "y": -10,
          "z": -2,
          "color": "#2d211c"
        },
        {
          "x": -2,
          "y": -10,
          "z": -2,
          "color": "#2d211c"
        },
        {
          "x": -7,
          "y": -9,
          "z": -2,
          "color": "#2d211c"
        },
        {
          "x": -6,
          "y": -9,
          "z": -2,
          "color": "#2d211c"
        },
        {
          "x": -5,
          "y": -9,
          "z": -2,
          "color": "#2d211c"
        },
        {
          "x": -4,
          "y": -9,
          "z": -2,
          "color": "#2d211c"
        },
        {
          "x": -3,
          "y": -9,
          "z": -2,
          "color": "#2d211c"
        },
        {
          "x": -2,
          "y": -9,
          "z": -2,
          "color": "#2d211c"
        },
        {
          "x": -1,
          "y": -9,
          "z": -2,
          "color": "#2d211c"
        },
        {
          "x": -6,
          "y": -8,
          "z": -2,
          "color": "#2d211c"
        },
        {
          "x": -5,
          "y": -8,
          "z": -2,
          "color": "#2d211c"
        },
        {
          "x": -4,
          "y": -8,
          "z": -2,
          "color": "#2d211c"
        },
        {
          "x": -3,
          "y": -8,
          "z": -2,
          "color": "#2d211c"
        },
        {
          "x": -2,
          "y": -8,
          "z": -2,
          "color": "#2d211c"
        },
        {
          "x": -1,
          "y": -8,
          "z": -2,
          "color": "#2d211c"
        },
        {
          "x": -5,
          "y": -7,
          "z": -2,
          "color": "#2d211c"
        },
        {
          "x": -4,
          "y": -7,
          "z": -2,
          "color": "#2d211c"
        },
        {
          "x": -3,
          "y": -7,
          "z": -2,
          "color": "#2d211c"
        },
        {
          "x": -2,
          "y": -7,
          "z": -2,
          "color": "#2d211c"
        },
        {
          "x": -1,
          "y": -7,
          "z": -2,
          "color": "#2d211c"
        },
        {
          "x": 0,
          "y": -7,
          "z": -2,
          "color": "#2d211c"
        },
        {
          "x": -4,
          "y": -6,
          "z": -2,
          "color": "#2d211c"
        },
        {
          "x": -3,
          "y": -6,
          "z": -2,
          "color": "#2d211c"
        },
        {
          "x": -2,
          "y": -6,
          "z": -2,
          "color": "#2d211c"
        },
        {
          "x": -1,
          "y": -6,
          "z": -2,
          "color": "#2d211c"
        },
        {
          "x": 0,
          "y": -6,
          "z": -2,
          "color": "#2d211c"
        },
        {
          "x": -3,
          "y": -1,
          "z": -2,
          "color": "#302923"
        },
        {
          "x": -2,
          "y": -1,
          "z": -2,
          "color": "#302923"
        },
        {
          "x": -2,
          "y": 0,
          "z": -2,
          "color": "#302923"
        },
        {
          "x": -1,
          "y": 0,
          "z": -2,
          "color": "#302923"
        },
        {
          "x": -4,
          "y": 6,
          "z": -2,
          "color": "#2d211c"
        },
        {
          "x": -3,
          "y": 6,
          "z": -2,
          "color": "#2d211c"
        },
        {
          "x": -2,
          "y": 6,
          "z": -2,
          "color": "#2d211c"
        },
        {
          "x": -1,
          "y": 6,
          "z": -2,
          "color": "#2d211c"
        },
        {
          "x": 0,
          "y": 6,
          "z": -2,
          "color": "#2d211c"
        },
        {
          "x": -5,
          "y": 7,
          "z": -2,
          "color": "#2d211c"
        },
        {
          "x": -4,
          "y": 7,
          "z": -2,
          "color": "#2d211c"
        },
        {
          "x": -3,
          "y": 7,
          "z": -2,
          "color": "#2d211c"
        },
        {
          "x": -2,
          "y": 7,
          "z": -2,
          "color": "#2d211c"
        },
        {
          "x": -1,
          "y": 7,
          "z": -2,
          "color": "#2d211c"
        },
        {
          "x": 0,
          "y": 7,
          "z": -2,
          "color": "#2d211c"
        },
        {
          "x": -6,
          "y": 8,
          "z": -2,
          "color": "#2d211c"
        },
        {
          "x": -5,
          "y": 8,
          "z": -2,
          "color": "#2d211c"
        },
        {
          "x": -4,
          "y": 8,
          "z": -2,
          "color": "#2d211c"
        },
        {
          "x": -3,
          "y": 8,
          "z": -2,
          "color": "#2d211c"
        },
        {
          "x": -2,
          "y": 8,
          "z": -2,
          "color": "#2d211c"
        },
        {
          "x": -1,
          "y": 8,
          "z": -2,
          "color": "#2d211c"
        },
        {
          "x": -7,
          "y": 9,
          "z": -2,
          "color": "#2d211c"
        },
        {
          "x": -6,
          "y": 9,
          "z": -2,
          "color": "#b37443"
        },
        {
          "x": -5,
          "y": 9,
          "z": -2,
          "color": "#2d211c"
        },
        {
          "x": -4,
          "y": 9,
          "z": -2,
          "color": "#2d211c"
        },
        {
          "x": -3,
          "y": 9,
          "z": -2,
          "color": "#2d211c"
        },
        {
          "x": -2,
          "y": 9,
          "z": -2,
          "color": "#2d211c"
        },
        {
          "x": -1,
          "y": 9,
          "z": -2,
          "color": "#2d211c"
        },
        {
          "x": -8,
          "y": 10,
          "z": -2,
          "color": "#2d211c"
        },
        {
          "x": -7,
          "y": 10,
          "z": -2,
          "color": "#2d211c"
        },
        {
          "x": -6,
          "y": 10,
          "z": -2,
          "color": "#2d211c"
        },
        {
          "x": -5,
          "y": 10,
          "z": -2,
          "color": "#2d211c"
        },
        {
          "x": -4,
          "y": 10,
          "z": -2,
          "color": "#2d211c"
        },
        {
          "x": -3,
          "y": 10,
          "z": -2,
          "color": "#2d211c"
        },
        {
          "x": -2,
          "y": 10,
          "z": -2,
          "color": "#2d211c"
        },
        {
          "x": -9,
          "y": 11,
          "z": -2,
          "color": "#2d211c"
        },
        {
          "x": -8,
          "y": 11,
          "z": -2,
          "color": "#2d211c"
        },
        {
          "x": -7,
          "y": 11,
          "z": -2,
          "color": "#2d211c"
        },
        {
          "x": -6,
          "y": 11,
          "z": -2,
          "color": "#2d211c"
        },
        {
          "x": -5,
          "y": 11,
          "z": -2,
          "color": "#2d211c"
        },
        {
          "x": -4,
          "y": 11,
          "z": -2,
          "color": "#2d211c"
        },
        {
          "x": -3,
          "y": 11,
          "z": -2,
          "color": "#2d211c"
        },
        {
          "x": -2,
          "y": 11,
          "z": -2,
          "color": "#2d211c"
        },
        {
          "x": -9,
          "y": 12,
          "z": -2,
          "color": "#2d211c"
        },
        {
          "x": -8,
          "y": 12,
          "z": -2,
          "color": "#2d211c"
        },
        {
          "x": -7,
          "y": 12,
          "z": -2,
          "color": "#2d211c"
        },
        {
          "x": -6,
          "y": 12,
          "z": -2,
          "color": "#2d211c"
        },
        {
          "x": -5,
          "y": 12,
          "z": -2,
          "color": "#2d211c"
        },
        {
          "x": -4,
          "y": 12,
          "z": -2,
          "color": "#2d211c"
        },
        {
          "x": -3,
          "y": 12,
          "z": -2,
          "color": "#2d211c"
        },
        {
          "x": -10,
          "y": 13,
          "z": -2,
          "color": "#2d211c"
        },
        {
          "x": -9,
          "y": 13,
          "z": -2,
          "color": "#2d211c"
        },
        {
          "x": -8,
          "y": 13,
          "z": -2,
          "color": "#2d211c"
        },
        {
          "x": -7,
          "y": 13,
          "z": -2,
          "color": "#2d211c"
        },
        {
          "x": -6,
          "y": 13,
          "z": -2,
          "color": "#2d211c"
        },
        {
          "x": -5,
          "y": 13,
          "z": -2,
          "color": "#2d211c"
        },
        {
          "x": -4,
          "y": 13,
          "z": -2,
          "color": "#2d211c"
        },
        {
          "x": -3,
          "y": 13,
          "z": -2,
          "color": "#2d211c"
        },
        {
          "x": -11,
          "y": 14,
          "z": -2,
          "color": "#2d211c"
        },
        {
          "x": -10,
          "y": 14,
          "z": -2,
          "color": "#2d211c"
        },
        {
          "x": -9,
          "y": 14,
          "z": -2,
          "color": "#2d211c"
        },
        {
          "x": -8,
          "y": 14,
          "z": -2,
          "color": "#2d211c"
        },
        {
          "x": -7,
          "y": 14,
          "z": -2,
          "color": "#2d211c"
        },
        {
          "x": -6,
          "y": 14,
          "z": -2,
          "color": "#2d211c"
        },
        {
          "x": -5,
          "y": 14,
          "z": -2,
          "color": "#2d211c"
        },
        {
          "x": -4,
          "y": 14,
          "z": -2,
          "color": "#2d211c"
        },
        {
          "x": -13,
          "y": 15,
          "z": -2,
          "color": "#ddd6c8"
        },
        {
          "x": -14,
          "y": -15,
          "z": -1,
          "color": "#6d3f28"
        },
        {
          "x": -13,
          "y": -15,
          "z": -1,
          "color": "#6d3f28"
        },
        {
          "x": -12,
          "y": -15,
          "z": -1,
          "color": "#8f5b35"
        },
        {
          "x": -11,
          "y": -15,
          "z": -1,
          "color": "#8f5b35"
        },
        {
          "x": -10,
          "y": -15,
          "z": -1,
          "color": "#8f5b35"
        },
        {
          "x": -9,
          "y": -15,
          "z": -1,
          "color": "#8f5b35"
        },
        {
          "x": -8,
          "y": -15,
          "z": -1,
          "color": "#8f5b35"
        },
        {
          "x": -7,
          "y": -15,
          "z": -1,
          "color": "#8f5b35"
        },
        {
          "x": -6,
          "y": -15,
          "z": -1,
          "color": "#8f5b35"
        },
        {
          "x": -5,
          "y": -15,
          "z": -1,
          "color": "#8f5b35"
        },
        {
          "x": -4,
          "y": -15,
          "z": -1,
          "color": "#8f5b35"
        },
        {
          "x": -3,
          "y": -15,
          "z": -1,
          "color": "#6d3f28"
        },
        {
          "x": -2,
          "y": -15,
          "z": -1,
          "color": "#6d3f28"
        },
        {
          "x": -13,
          "y": -14,
          "z": -1,
          "color": "#6d3f28"
        },
        {
          "x": -12,
          "y": -14,
          "z": -1,
          "color": "#6d3f28"
        },
        {
          "x": -11,
          "y": -14,
          "z": -1,
          "color": "#8f5b35"
        },
        {
          "x": -10,
          "y": -14,
          "z": -1,
          "color": "#8f5b35"
        },
        {
          "x": -9,
          "y": -14,
          "z": -1,
          "color": "#8f5b35"
        },
        {
          "x": -8,
          "y": -14,
          "z": -1,
          "color": "#8f5b35"
        },
        {
          "x": -7,
          "y": -14,
          "z": -1,
          "color": "#8f5b35"
        },
        {
          "x": -6,
          "y": -14,
          "z": -1,
          "color": "#8f5b35"
        },
        {
          "x": -5,
          "y": -14,
          "z": -1,
          "color": "#8f5b35"
        },
        {
          "x": -4,
          "y": -14,
          "z": -1,
          "color": "#8f5b35"
        },
        {
          "x": -3,
          "y": -14,
          "z": -1,
          "color": "#6d3f28"
        },
        {
          "x": -2,
          "y": -14,
          "z": -1,
          "color": "#6d3f28"
        },
        {
          "x": -12,
          "y": -13,
          "z": -1,
          "color": "#6d3f28"
        },
        {
          "x": -11,
          "y": -13,
          "z": -1,
          "color": "#6d3f28"
        },
        {
          "x": -10,
          "y": -13,
          "z": -1,
          "color": "#8f5b35"
        },
        {
          "x": -9,
          "y": -13,
          "z": -1,
          "color": "#8f5b35"
        },
        {
          "x": -8,
          "y": -13,
          "z": -1,
          "color": "#8f5b35"
        },
        {
          "x": -7,
          "y": -13,
          "z": -1,
          "color": "#8f5b35"
        },
        {
          "x": -6,
          "y": -13,
          "z": -1,
          "color": "#8f5b35"
        },
        {
          "x": -5,
          "y": -13,
          "z": -1,
          "color": "#8f5b35"
        },
        {
          "x": -4,
          "y": -13,
          "z": -1,
          "color": "#8f5b35"
        },
        {
          "x": -3,
          "y": -13,
          "z": -1,
          "color": "#8f5b35"
        },
        {
          "x": -2,
          "y": -13,
          "z": -1,
          "color": "#6d3f28"
        },
        {
          "x": -1,
          "y": -13,
          "z": -1,
          "color": "#6d3f28"
        },
        {
          "x": -11,
          "y": -12,
          "z": -1,
          "color": "#6d3f28"
        },
        {
          "x": -10,
          "y": -12,
          "z": -1,
          "color": "#4d2c22"
        },
        {
          "x": -9,
          "y": -12,
          "z": -1,
          "color": "#8f5b35"
        },
        {
          "x": -8,
          "y": -12,
          "z": -1,
          "color": "#8f5b35"
        },
        {
          "x": -7,
          "y": -12,
          "z": -1,
          "color": "#8f5b35"
        },
        {
          "x": -6,
          "y": -12,
          "z": -1,
          "color": "#8f5b35"
        },
        {
          "x": -5,
          "y": -12,
          "z": -1,
          "color": "#8f5b35"
        },
        {
          "x": -4,
          "y": -12,
          "z": -1,
          "color": "#8f5b35"
        },
        {
          "x": -3,
          "y": -12,
          "z": -1,
          "color": "#8f5b35"
        },
        {
          "x": -2,
          "y": -12,
          "z": -1,
          "color": "#6d3f28"
        },
        {
          "x": -1,
          "y": -12,
          "z": -1,
          "color": "#6d3f28"
        },
        {
          "x": -11,
          "y": -11,
          "z": -1,
          "color": "#6d3f28"
        },
        {
          "x": -10,
          "y": -11,
          "z": -1,
          "color": "#6d3f28"
        },
        {
          "x": -9,
          "y": -11,
          "z": -1,
          "color": "#8f5b35"
        },
        {
          "x": -8,
          "y": -11,
          "z": -1,
          "color": "#8f5b35"
        },
        {
          "x": -7,
          "y": -11,
          "z": -1,
          "color": "#8f5b35"
        },
        {
          "x": -6,
          "y": -11,
          "z": -1,
          "color": "#8f5b35"
        },
        {
          "x": -5,
          "y": -11,
          "z": -1,
          "color": "#8f5b35"
        },
        {
          "x": -4,
          "y": -11,
          "z": -1,
          "color": "#8f5b35"
        },
        {
          "x": -3,
          "y": -11,
          "z": -1,
          "color": "#8f5b35"
        },
        {
          "x": -2,
          "y": -11,
          "z": -1,
          "color": "#8f5b35"
        },
        {
          "x": -1,
          "y": -11,
          "z": -1,
          "color": "#6d3f28"
        },
        {
          "x": 0,
          "y": -11,
          "z": -1,
          "color": "#6d3f28"
        },
        {
          "x": -10,
          "y": -10,
          "z": -1,
          "color": "#6d3f28"
        },
        {
          "x": -9,
          "y": -10,
          "z": -1,
          "color": "#6d3f28"
        },
        {
          "x": -8,
          "y": -10,
          "z": -1,
          "color": "#8f5b35"
        },
        {
          "x": -7,
          "y": -10,
          "z": -1,
          "color": "#8f5b35"
        },
        {
          "x": -6,
          "y": -10,
          "z": -1,
          "color": "#8f5b35"
        },
        {
          "x": -5,
          "y": -10,
          "z": -1,
          "color": "#8f5b35"
        },
        {
          "x": -4,
          "y": -10,
          "z": -1,
          "color": "#8f5b35"
        },
        {
          "x": -3,
          "y": -10,
          "z": -1,
          "color": "#8f5b35"
        },
        {
          "x": -2,
          "y": -10,
          "z": -1,
          "color": "#8f5b35"
        },
        {
          "x": -1,
          "y": -10,
          "z": -1,
          "color": "#6d3f28"
        },
        {
          "x": 0,
          "y": -10,
          "z": -1,
          "color": "#6d3f28"
        },
        {
          "x": -9,
          "y": -9,
          "z": -1,
          "color": "#6d3f28"
        },
        {
          "x": -8,
          "y": -9,
          "z": -1,
          "color": "#6d3f28"
        },
        {
          "x": -7,
          "y": -9,
          "z": -1,
          "color": "#8f5b35"
        },
        {
          "x": -6,
          "y": -9,
          "z": -1,
          "color": "#8f5b35"
        },
        {
          "x": -5,
          "y": -9,
          "z": -1,
          "color": "#8f5b35"
        },
        {
          "x": -4,
          "y": -9,
          "z": -1,
          "color": "#8f5b35"
        },
        {
          "x": -3,
          "y": -9,
          "z": -1,
          "color": "#8f5b35"
        },
        {
          "x": -2,
          "y": -9,
          "z": -1,
          "color": "#8f5b35"
        },
        {
          "x": -1,
          "y": -9,
          "z": -1,
          "color": "#8f5b35"
        },
        {
          "x": 0,
          "y": -9,
          "z": -1,
          "color": "#6d3f28"
        },
        {
          "x": 1,
          "y": -9,
          "z": -1,
          "color": "#6d3f28"
        },
        {
          "x": -8,
          "y": -8,
          "z": -1,
          "color": "#6d3f28"
        },
        {
          "x": -7,
          "y": -8,
          "z": -1,
          "color": "#4d2c22"
        },
        {
          "x": -6,
          "y": -8,
          "z": -1,
          "color": "#8f5b35"
        },
        {
          "x": -5,
          "y": -8,
          "z": -1,
          "color": "#8f5b35"
        },
        {
          "x": -4,
          "y": -8,
          "z": -1,
          "color": "#8f5b35"
        },
        {
          "x": -3,
          "y": -8,
          "z": -1,
          "color": "#8f5b35"
        },
        {
          "x": -2,
          "y": -8,
          "z": -1,
          "color": "#8f5b35"
        },
        {
          "x": -1,
          "y": -8,
          "z": -1,
          "color": "#8f5b35"
        },
        {
          "x": 0,
          "y": -8,
          "z": -1,
          "color": "#6d3f28"
        },
        {
          "x": 1,
          "y": -8,
          "z": -1,
          "color": "#6d3f28"
        },
        {
          "x": -7,
          "y": -7,
          "z": -1,
          "color": "#6d3f28"
        },
        {
          "x": -6,
          "y": -7,
          "z": -1,
          "color": "#6d3f28"
        },
        {
          "x": -5,
          "y": -7,
          "z": -1,
          "color": "#8f5b35"
        },
        {
          "x": -4,
          "y": -7,
          "z": -1,
          "color": "#a3693d"
        },
        {
          "x": -3,
          "y": -7,
          "z": -1,
          "color": "#8f5b35"
        },
        {
          "x": -2,
          "y": -7,
          "z": -1,
          "color": "#8f5b35"
        },
        {
          "x": -1,
          "y": -7,
          "z": -1,
          "color": "#8f5b35"
        },
        {
          "x": 0,
          "y": -7,
          "z": -1,
          "color": "#8f5b35"
        },
        {
          "x": 1,
          "y": -7,
          "z": -1,
          "color": "#6d3f28"
        },
        {
          "x": 2,
          "y": -7,
          "z": -1,
          "color": "#6d3f28"
        },
        {
          "x": -6,
          "y": -6,
          "z": -1,
          "color": "#6d3f28"
        },
        {
          "x": -5,
          "y": -6,
          "z": -1,
          "color": "#6d3f28"
        },
        {
          "x": -4,
          "y": -6,
          "z": -1,
          "color": "#8f5b35"
        },
        {
          "x": -3,
          "y": -6,
          "z": -1,
          "color": "#8f5b35"
        },
        {
          "x": -2,
          "y": -6,
          "z": -1,
          "color": "#8f5b35"
        },
        {
          "x": -1,
          "y": -6,
          "z": -1,
          "color": "#8f5b35"
        },
        {
          "x": 0,
          "y": -6,
          "z": -1,
          "color": "#8f5b35"
        },
        {
          "x": 1,
          "y": -6,
          "z": -1,
          "color": "#6d3f28"
        },
        {
          "x": 2,
          "y": -6,
          "z": -1,
          "color": "#6d3f28"
        },
        {
          "x": -6,
          "y": -5,
          "z": -1,
          "color": "#6d3f28"
        },
        {
          "x": -5,
          "y": -5,
          "z": -1,
          "color": "#6d3f28"
        },
        {
          "x": -4,
          "y": -5,
          "z": -1,
          "color": "#8f5b35"
        },
        {
          "x": -3,
          "y": -5,
          "z": -1,
          "color": "#8f5b35"
        },
        {
          "x": -2,
          "y": -5,
          "z": -1,
          "color": "#8f5b35"
        },
        {
          "x": -1,
          "y": -5,
          "z": -1,
          "color": "#8f5b35"
        },
        {
          "x": 0,
          "y": -5,
          "z": -1,
          "color": "#8f5b35"
        },
        {
          "x": 1,
          "y": -5,
          "z": -1,
          "color": "#6d3f28"
        },
        {
          "x": 2,
          "y": -5,
          "z": -1,
          "color": "#6d3f28"
        },
        {
          "x": -5,
          "y": -4,
          "z": -1,
          "color": "#6d3f28"
        },
        {
          "x": -4,
          "y": -4,
          "z": -1,
          "color": "#4d2c22"
        },
        {
          "x": -3,
          "y": -4,
          "z": -1,
          "color": "#8f5b35"
        },
        {
          "x": -2,
          "y": -4,
          "z": -1,
          "color": "#8f5b35"
        },
        {
          "x": -1,
          "y": -4,
          "z": -1,
          "color": "#8f5b35"
        },
        {
          "x": 0,
          "y": -4,
          "z": -1,
          "color": "#8f5b35"
        },
        {
          "x": 1,
          "y": -4,
          "z": -1,
          "color": "#6d3f28"
        },
        {
          "x": 2,
          "y": -4,
          "z": -1,
          "color": "#6d3f28"
        },
        {
          "x": -4,
          "y": -3,
          "z": -1,
          "color": "#6d3f28"
        },
        {
          "x": -3,
          "y": -3,
          "z": -1,
          "color": "#6d3f28"
        },
        {
          "x": -2,
          "y": -3,
          "z": -1,
          "color": "#8f5b35"
        },
        {
          "x": -1,
          "y": -3,
          "z": -1,
          "color": "#8f5b35"
        },
        {
          "x": 0,
          "y": -3,
          "z": -1,
          "color": "#8f5b35"
        },
        {
          "x": 1,
          "y": -3,
          "z": -1,
          "color": "#6d3f28"
        },
        {
          "x": 2,
          "y": -3,
          "z": -1,
          "color": "#6d3f28"
        },
        {
          "x": -3,
          "y": -2,
          "z": -1,
          "color": "#6d3f28"
        },
        {
          "x": -2,
          "y": -2,
          "z": -1,
          "color": "#6d3f28"
        },
        {
          "x": -1,
          "y": -2,
          "z": -1,
          "color": "#8f5b35"
        },
        {
          "x": 0,
          "y": -2,
          "z": -1,
          "color": "#8f5b35"
        },
        {
          "x": 1,
          "y": -2,
          "z": -1,
          "color": "#6d3f28"
        },
        {
          "x": 2,
          "y": -2,
          "z": -1,
          "color": "#6d3f28"
        },
        {
          "x": -1,
          "y": -1,
          "z": -1,
          "color": "#302923"
        },
        {
          "x": 2,
          "y": -1,
          "z": -1,
          "color": "#9a5347"
        },
        {
          "x": 3,
          "y": -1,
          "z": -1,
          "color": "#9a5347"
        },
        {
          "x": 4,
          "y": -1,
          "z": -1,
          "color": "#9a5347"
        },
        {
          "x": 8,
          "y": -1,
          "z": -1,
          "color": "#c0aaa0"
        },
        {
          "x": 9,
          "y": -1,
          "z": -1,
          "color": "#c0aaa0"
        },
        {
          "x": 10,
          "y": -1,
          "z": -1,
          "color": "#c0aaa0"
        },
        {
          "x": 11,
          "y": -1,
          "z": -1,
          "color": "#c0aaa0"
        },
        {
          "x": 12,
          "y": -1,
          "z": -1,
          "color": "#c0aaa0"
        },
        {
          "x": 13,
          "y": -1,
          "z": -1,
          "color": "#c0aaa0"
        },
        {
          "x": 14,
          "y": -1,
          "z": -1,
          "color": "#302923"
        },
        {
          "x": 0,
          "y": 0,
          "z": -1,
          "color": "#302923"
        },
        {
          "x": 2,
          "y": 0,
          "z": -1,
          "color": "#9a5347"
        },
        {
          "x": 3,
          "y": 0,
          "z": -1,
          "color": "#9a5347"
        },
        {
          "x": 4,
          "y": 0,
          "z": -1,
          "color": "#9a5347"
        },
        {
          "x": 8,
          "y": 0,
          "z": -1,
          "color": "#c0aaa0"
        },
        {
          "x": 9,
          "y": 0,
          "z": -1,
          "color": "#c0aaa0"
        },
        {
          "x": 10,
          "y": 0,
          "z": -1,
          "color": "#c0aaa0"
        },
        {
          "x": 11,
          "y": 0,
          "z": -1,
          "color": "#c0aaa0"
        },
        {
          "x": 12,
          "y": 0,
          "z": -1,
          "color": "#c0aaa0"
        },
        {
